Workbook

Sheet Lineal Mixto
A1: 📊 SIMULACIÓN — Lineal Mixto
A2: Motor de Validación Multiteoría • Exportado automáticamente
A4: i | B4: X_i | C4: R_i | D4: Estado | F4: ⚙️ Parámetros | H4: 🛡️ AUDITORÍA ESTADÍSTICA
A5: 1 | B5: =MOD($G$6*$G$5 + $G$7, $G$8) | C5: =B5/$G$8 | D5: ✓ | F5: Semilla (X0) | G5: 4 | H5: Prueba | I5: Estadístico | J5: Valor Crítico | K5: Estado
A6: 2 | B6: =MOD($G$6*B5 + $G$7, $G$8) | C6: =B6/$G$8 | D6: ✓ | F6: a | G6: 5 | H6: Promedios (Z_0) | I6: =ABS('Auxiliares'!$B$8) | J6: 1.96 | K6: =IF(I6<J6,"✅ APROBADO","❌ RECHAZADO")
A7: 3 | B7: =MOD($G$6*B6 + $G$7, $G$8) | C7: =B7/$G$8 | D7: ✓ | F7: c | G7: 7 | H7: Frecuencias (Chi-cuadrada) | I7: =SUM('Auxiliares'!$F$12:$F$21) | J7: 16.919 | K7: =IF(I7<J7,"✅ APROBADO","❌ RECHAZADO")
A8: 4 | B8: =MOD($G$6*B7 + $G$7, $G$8) | C8: =B8/$G$8 | D8: ✓ | F8: m | G8: 8 | H8: Kolmogorov-Smirnov (D_n) | I8: =MAX('Auxiliares'!$D$25:$D$44) | J8: =1.36/SQRT(COUNT($C$5:$C$24)) | K8: =IF(I8<J8,"✅ APROBADO","❌ RECHAZADO")
A9: 5 | B9: =MOD($G$6*B8 + $G$7, $G$8) | C9: =B9/$G$8 | D9: ✓ | F9: N | G9: 20 | H9: Entropía de Shannon (Bits) | I9: =SUM('Auxiliares'!$H$12:$H$21) | J9: 3.2 | K9: =IF(I9>J9,"✅ APROBADO","❌ RECHAZADO")
A10: 6 | B10: =MOD($G$6*B9 + $G$7, $G$8) | C10: =B10/$G$8 | D10: ✓ | H10: Monte Carlo para Pi (Error Absoluto) | I10: ='Auxiliares'!$B$61 | J10: 0.15 | K10: =IF(I10<J10,"✅ APROBADO","❌ RECHAZADO")
A11: 7 | B11: =MOD($G$6*B10 + $G$7, $G$8) | C11: =B11/$G$8 | D11: ✓ | H11: Distancia (Coss Bu) | I11: =SUM('Auxiliares'!$E$91:$E$94) | J11: 7.81 | K11: =IF(I11<J11,"✅ APROBADO","❌ RECHAZADO")
A12: 8 | B12: =MOD($G$6*B11 + $G$7, $G$8) | C12: =B12/$G$8 | D12: ✓ | H12: Series (Coss Bu) | I12: ='Auxiliares'!$B$147 | J12: 36.41 | K12: =IF(I12<J12,"✅ APROBADO","❌ RECHAZADO")
A13: 9 | B13: =MOD($G$6*B12 + $G$7, $G$8) | C13: =B13/$G$8 | D13: 🔄 Ciclo
A14: 10 | B14: =MOD($G$6*B13 + $G$7, $G$8) | C14: =B14/$G$8 | D14: 🔄 Ciclo
A15: 11 | B15: =MOD($G$6*B14 + $G$7, $G$8) | C15: =B15/$G$8 | D15: 🔄 Ciclo
A16: 12 | B16: =MOD($G$6*B15 + $G$7, $G$8) | C16: =B16/$G$8 | D16: 🔄 Ciclo
A17: 13 | B17: =MOD($G$6*B16 + $G$7, $G$8) | C17: =B17/$G$8 | D17: 🔄 Ciclo
A18: 14 | B18: =MOD($G$6*B17 + $G$7, $G$8) | C18: =B18/$G$8 | D18: 🔄 Ciclo
A19: 15 | B19: =MOD($G$6*B18 + $G$7, $G$8) | C19: =B19/$G$8 | D19: 🔄 Ciclo
A20: 16 | B20: =MOD($G$6*B19 + $G$7, $G$8) | C20: =B20/$G$8 | D20: 🔄 Ciclo
A21: 17 | B21: =MOD($G$6*B20 + $G$7, $G$8) | C21: =B21/$G$8 | D21: 🔄 Ciclo
A22: 18 | B22: =MOD($G$6*B21 + $G$7, $G$8) | C22: =B22/$G$8 | D22: 🔄 Ciclo
A23: 19 | B23: =MOD($G$6*B22 + $G$7, $G$8) | C23: =B23/$G$8 | D23: 🔄 Ciclo
A24: 20 | B24: =MOD($G$6*B23 + $G$7, $G$8) | C24: =B24/$G$8 | D24: 🔄 Ciclo
A27: Total generados: | C27: 20
A28: Ciclos detectados: | C28: 12

Sheet Auxiliares
A1: 🧮 Auxiliares — Trazabilidad de Fórmulas
A2: Cada celda de esta hoja es una fórmula real. El panel de auditoría de "Lineal Mixto" referencia estos cálculos, así que todo se recalcula si cambian los parámetros.
A4: 📐 Prueba de Promedios — Z_0
A5: Cantidad | B5: Valor
A6: Media (R̄) = AVERAGE(R_i) | B6: =AVERAGE('Lineal Mixto'!$C$5:$C$24)
A7: N = COUNT(R_i) | B7: =COUNT('Lineal Mixto'!$C$5:$C$24)
A8: Z_0 = (R̄-0.5)·√N / √(1/12) [sin valor absoluto] | B8: =(B6-0.5)*SQRT(B7)/SQRT(1/12)
A10: 📊 Prueba de Frecuencias / Entropía — Tabla de 10 clases
A11: Clase (k) | B11: Límite inf. | C11: Límite sup. | D11: Oi (observado) | E11: Ei (esperado) | F11: (Oi-Ei)²/Ei | G11: pi = Oi/N | H11: Aporte entropía -piㆍlog2(pi)
A12: 0 | B12: =A12/10 | C12: =(A12+1)/10 | D12: =COUNTIFS('Lineal Mixto'!$C$5:$C$24,">="&B12,'Lineal Mixto'!$C$5:$C$24,"<"&C12) | E12: =COUNT('Lineal Mixto'!$C$5:$C$24)/10 | F12: =(D12-E12)^2/E12 | G12: =D12/COUNT('Lineal Mixto'!$C$5:$C$24) | H12: =IF(D12>0,-G12*LOG(G12,2),0)
A13: 1 | B13: =A13/10 | C13: =(A13+1)/10 | D13: =COUNTIFS('Lineal Mixto'!$C$5:$C$24,">="&B13,'Lineal Mixto'!$C$5:$C$24,"<"&C13) | E13: =COUNT('Lineal Mixto'!$C$5:$C$24)/10 | F13: =(D13-E13)^2/E13 | G13: =D13/COUNT('Lineal Mixto'!$C$5:$C$24) | H13: =IF(D13>0,-G13*LOG(G13,2),0)
A14: 2 | B14: =A14/10 | C14: =(A14+1)/10 | D14: =COUNTIFS('Lineal Mixto'!$C$5:$C$24,">="&B14,'Lineal Mixto'!$C$5:$C$24,"<"&C14) | E14: =COUNT('Lineal Mixto'!$C$5:$C$24)/10 | F14: =(D14-E14)^2/E14 | G14: =D14/COUNT('Lineal Mixto'!$C$5:$C$24) | H14: =IF(D14>0,-G14*LOG(G14,2),0)
A15: 3 | B15: =A15/10 | C15: =(A15+1)/10 | D15: =COUNTIFS('Lineal Mixto'!$C$5:$C$24,">="&B15,'Lineal Mixto'!$C$5:$C$24,"<"&C15) | E15: =COUNT('Lineal Mixto'!$C$5:$C$24)/10 | F15: =(D15-E15)^2/E15 | G15: =D15/COUNT('Lineal Mixto'!$C$5:$C$24) | H15: =IF(D15>0,-G15*LOG(G15,2),0)
A16: 4 | B16: =A16/10 | C16: =(A16+1)/10 | D16: =COUNTIFS('Lineal Mixto'!$C$5:$C$24,">="&B16,'Lineal Mixto'!$C$5:$C$24,"<"&C16) | E16: =COUNT('Lineal Mixto'!$C$5:$C$24)/10 | F16: =(D16-E16)^2/E16 | G16: =D16/COUNT('Lineal Mixto'!$C$5:$C$24) | H16: =IF(D16>0,-G16*LOG(G16,2),0)
A17: 5 | B17: =A17/10 | C17: =(A17+1)/10 | D17: =COUNTIFS('Lineal Mixto'!$C$5:$C$24,">="&B17,'Lineal Mixto'!$C$5:$C$24,"<"&C17) | E17: =COUNT('Lineal Mixto'!$C$5:$C$24)/10 | F17: =(D17-E17)^2/E17 | G17: =D17/COUNT('Lineal Mixto'!$C$5:$C$24) | H17: =IF(D17>0,-G17*LOG(G17,2),0)
A18: 6 | B18: =A18/10 | C18: =(A18+1)/10 | D18: =COUNTIFS('Lineal Mixto'!$C$5:$C$24,">="&B18,'Lineal Mixto'!$C$5:$C$24,"<"&C18) | E18: =COUNT('Lineal Mixto'!$C$5:$C$24)/10 | F18: =(D18-E18)^2/E18 | G18: =D18/COUNT('Lineal Mixto'!$C$5:$C$24) | H18: =IF(D18>0,-G18*LOG(G18,2),0)
A19: 7 | B19: =A19/10 | C19: =(A19+1)/10 | D19: =COUNTIFS('Lineal Mixto'!$C$5:$C$24,">="&B19,'Lineal Mixto'!$C$5:$C$24,"<"&C19) | E19: =COUNT('Lineal Mixto'!$C$5:$C$24)/10 | F19: =(D19-E19)^2/E19 | G19: =D19/COUNT('Lineal Mixto'!$C$5:$C$24) | H19: =IF(D19>0,-G19*LOG(G19,2),0)
A20: 8 | B20: =A20/10 | C20: =(A20+1)/10 | D20: =COUNTIFS('Lineal Mixto'!$C$5:$C$24,">="&B20,'Lineal Mixto'!$C$5:$C$24,"<"&C20) | E20: =COUNT('Lineal Mixto'!$C$5:$C$24)/10 | F20: =(D20-E20)^2/E20 | G20: =D20/COUNT('Lineal Mixto'!$C$5:$C$24) | H20: =IF(D20>0,-G20*LOG(G20,2),0)
A21: 9 | B21: =A21/10 | C21: 1 | D21: =COUNTIFS('Lineal Mixto'!$C$5:$C$24,">="&B21) | E21: =COUNT('Lineal Mixto'!$C$5:$C$24)/10 | F21: =(D21-E21)^2/E21 | G21: =D21/COUNT('Lineal Mixto'!$C$5:$C$24) | H21: =IF(D21>0,-G21*LOG(G21,2),0)
A23: 📈 Kolmogorov-Smirnov — R_i ordenados ascendentemente
A24: k | B24: R(k) [k-ésimo menor] | C24: k/N | D24: |k/N - R(k)|
A25: 1 | B25: =SMALL('Lineal Mixto'!$C$5:$C$24,A25) | C25: =A25/COUNT('Lineal Mixto'!$C$5:$C$24) | D25: =ABS(C25-B25)
A26: 2 | B26: =SMALL('Lineal Mixto'!$C$5:$C$24,A26) | C26: =A26/COUNT('Lineal Mixto'!$C$5:$C$24) | D26: =ABS(C26-B26)
A27: 3 | B27: =SMALL('Lineal Mixto'!$C$5:$C$24,A27) | C27: =A27/COUNT('Lineal Mixto'!$C$5:$C$24) | D27: =ABS(C27-B27)
A28: 4 | B28: =SMALL('Lineal Mixto'!$C$5:$C$24,A28) | C28: =A28/COUNT('Lineal Mixto'!$C$5:$C$24) | D28: =ABS(C28-B28)
A29: 5 | B29: =SMALL('Lineal Mixto'!$C$5:$C$24,A29) | C29: =A29/COUNT('Lineal Mixto'!$C$5:$C$24) | D29: =ABS(C29-B29)
A30: 6 | B30: =SMALL('Lineal Mixto'!$C$5:$C$24,A30) | C30: =A30/COUNT('Lineal Mixto'!$C$5:$C$24) | D30: =ABS(C30-B30)
A31: 7 | B31: =SMALL('Lineal Mixto'!$C$5:$C$24,A31) | C31: =A31/COUNT('Lineal Mixto'!$C$5:$C$24) | D31: =ABS(C31-B31)
A32: 8 | B32: =SMALL('Lineal Mixto'!$C$5:$C$24,A32) | C32: =A32/COUNT('Lineal Mixto'!$C$5:$C$24) | D32: =ABS(C32-B32)
A33: 9 | B33: =SMALL('Lineal Mixto'!$C$5:$C$24,A33) | C33: =A33/COUNT('Lineal Mixto'!$C$5:$C$24) | D33: =ABS(C33-B33)
A34: 10 | B34: =SMALL('Lineal Mixto'!$C$5:$C$24,A34) | C34: =A34/COUNT('Lineal Mixto'!$C$5:$C$24) | D34: =ABS(C34-B34)
A35: 11 | B35: =SMALL('Lineal Mixto'!$C$5:$C$24,A35) | C35: =A35/COUNT('Lineal Mixto'!$C$5:$C$24) | D35: =ABS(C35-B35)
A36: 12 | B36: =SMALL('Lineal Mixto'!$C$5:$C$24,A36) | C36: =A36/COUNT('Lineal Mixto'!$C$5:$C$24) | D36: =ABS(C36-B36)
... A44: 20 | B44: =SMALL('Lineal Mixto'!$C$5:$C$24,A44) | C44: =A44/COUNT('Lineal Mixto'!$C$5:$C$24) | D44: =ABS(C44-B44)
A46: 🎯 Monte Carlo para Pi — Pares (R_2j-1, R_2j)
A47: Par (j) | B47: X = R(2j-1) | C47: Y = R(2j) | D47: X²+Y² | E47: ¿Dentro del círculo? (1/0)
A48: 1 | B48: =INDEX('Lineal Mixto'!$C$5:$C$24,2*A48-1) | C48: =INDEX('Lineal Mixto'!$C$5:$C$24,2*A48) | D48: =B48^2+C48^2 | E48: =IF(D48<=1,1,0)
A49: 2 | B49: =INDEX('Lineal Mixto'!$C$5:$C$24,2*A49-1) | C49: =INDEX('Lineal Mixto'!$C$5:$C$24,2*A49) | D49: =B49^2+C49^2 | E49: =IF(D49<=1,1,0)
A50: 3 | B50: =INDEX('Lineal Mixto'!$C$5:$C$24,2*A50-1) | C50: =INDEX('Lineal Mixto'!$C$5:$C$24,2*A50) | D50: =B50^2+C50^2 | E50: =IF(D50<=1,1,0)
A51: 4 | B51: =INDEX('Lineal Mixto'!$C$5:$C$24,2*A51-1) | C51: =INDEX('Lineal Mixto'!$C$5:$C$24,2*A51) | D51: =B51^2+C51^2 | E51: =IF(D51<=1,1,0)
...
