Workbook

Sheet Xorshift
A1: 📊 SIMULACIÓN — Xorshift
A2: Motor de Validación Multiteoría • Exportado automáticamente
A4: i | B4: X_i | C4: R_i | D4: Estado | F4: ⚙️ Parámetros | H4: 🛡️ AUDITORÍA ESTADÍSTICA
A5: 1 | B5: ='Auxiliares'!$E$6 | C5: =B5/4294967295 | D5: ✓ | F5: Semilla (X0) | G5: 123456789 | H5: Prueba | I5: Estadístico | J5: Valor Crítico | K5: Estado
A6: 2 | B6: ='Auxiliares'!$E$7 | C6: =B6/4294967295 | D6: ✓ | F6: a (Shift Izq) | G6: 13 | H6: Promedios (Z_0) | I6: =ABS('Auxiliares'!$B$32) | J6: 1.96 | K6: =IF(I6<J6,"✅ APROBADO","❌ RECHAZADO")
A7: 3 | B7: ='Auxiliares'!$E$8 | C7: =B7/4294967295 | D7: ✓ | F7: b (Shift Der) | G7: 17 | H7: Frecuencias (Chi-cuadrada) | I7: =SUM('Auxiliares'!$F$36:$F$45) | J7: 16.919 | K7: =IF(I7<J7,"✅ APROBADO","❌ RECHAZADO")
A8: 4 | B8: ='Auxiliares'!$E$9 | C8: =B8/4294967295 | D8: ✓ | F8: c (Shift Izq) | G8: 5 | H8: Kolmogorov-Smirnov (D_n) | I8: =MAX('Auxiliares'!$D$49:$D$68) | J8: =1.36/SQRT(COUNT($C$5:$C$24)) | K8: =IF(I8<J8,"✅ APROBADO","❌ RECHAZADO")
A9: 5 | B9: ='Auxiliares'!$E$10 | C9: =B9/4294967295 | D9: ✓ | F9: N | G9: 20 | H9: Entropía de Shannon (Bits) | I9: =SUM('Auxiliares'!$H$36:$H$45) | J9: 3.2 | K9: =IF(I9>J9,"✅ APROBADO","❌ RECHAZADO")
A10: 6 | B10: ='Auxiliares'!$E$11 | C10: =B10/4294967295 | D10: ✓ | H10: Monte Carlo para Pi (Error Absoluto) | I10: ='Auxiliares'!$B$85 | J10: 0.15 | K10: =IF(I10<J10,"✅ APROBADO","❌ RECHAZADO")
A11: 7 | B11: ='Auxiliares'!$E$12 | C11: =B11/4294967295 | D11: ✓ | H11: Distancia (Coss Bu) | I11: =SUM('Auxiliares'!$E$115:$E$118) | J11: 7.81 | K11: =IF(I11<J11,"✅ APROBADO","❌ RECHAZADO")
A12: 8 | B12: ='Auxiliares'!$E$13 | C12: =B12/4294967295 | D12: ✓ | H12: Series (Coss Bu) | I12: ='Auxiliares'!$B$171 | J12: 36.41 | K12: =IF(I12<J12,"✅ APROBADO","❌ RECHAZADO")
A13: 9 | B13: ='Auxiliares'!$E$14 | C13: =B13/4294967295 | D13: ✓
A14: 10 | B14: ='Auxiliares'!$E$15 | C14: =B14/4294967295 | D14: ✓
A15: 11 | B15: ='Auxiliares'!$E$16 | C15: =B15/4294967295 | D15: ✓
A16: 12 | B16: ='Auxiliares'!$E$17 | C16: =B16/4294967295 | D16: ✓
A17: 13 | B17: ='Auxiliares'!$E$18 | C17: =B17/4294967295 | D17: ✓
A18: 14 | B18: ='Auxiliares'!$E$19 | C18: =B18/4294967295 | D18: ✓
A19: 15 | B19: ='Auxiliares'!$E$20 | C19: =B19/4294967295 | D19: ✓
A20: 16 | B20: ='Auxiliares'!$E$21 | C20: =B20/4294967295 | D20: ✓
A21: 17 | B21: ='Auxiliares'!$E$22 | C21: =B21/4294967295 | D21: ✓
A22: 18 | B22: ='Auxiliares'!$E$23 | C22: =B22/4294967295 | D22: ✓
A23: 19 | B23: ='Auxiliares'!$E$24 | C23: =B23/4294967295 | D23: ✓
A24: 20 | B24: ='Auxiliares'!$E$25 | C24: =B24/4294967295 | D24: ✓
A27: Total generados: | C27: 20
A28: Ciclos detectados: | C28: 0

Sheet Auxiliares
A1: 🧮 Auxiliares — Trazabilidad de Fórmulas
A2: Cada celda de esta hoja es una fórmula real. El panel de auditoría de "Xorshift" referencia estos cálculos, así que todo se recalcula si cambian los parámetros.
A4: 🔀 Xorshift — Derivación de X_i mediante 3 desplazamientos XOR
A5: i | B5: X_(i-1) [previo] | C5: t1 = X ⊕ (X≪a) mod 2³² | D5: t2 = t1 ⊕ (t1≫b) | E5: t3 = t2 ⊕ (t2≪c) mod 2³² = X_i
A6: 1 | B6: ='Xorshift'!$G$5 | C6: =BITXOR(B6,MOD(B6,POWER(2,32-'Xorshift'!$G$6))*POWER(2,'Xorshift'!$G$6)) | D6: =BITXOR(C6,INT(C6/POWER(2,'Xorshift'!$G$7))) | E6: =BITXOR(D6,MOD(D6,POWER(2,32-'Xorshift'!$G$8))*POWER(2,'Xorshift'!$G$8))
A7: 2 | B7: =E6 | C7: =BITXOR(B7,MOD(B7,POWER(2,32-'Xorshift'!$G$6))*POWER(2,'Xorshift'!$G$6)) | D7: =BITXOR(C7,INT(C7/POWER(2,'Xorshift'!$G$7))) | E7: =BITXOR(D7,MOD(D7,POWER(2,32-'Xorshift'!$G$8))*POWER(2,'Xorshift'!$G$8))
A8: 3 | B8: =E7 | C8: =BITXOR(B8,MOD(B8,POWER(2,32-'Xorshift'!$G$6))*POWER(2,'Xorshift'!$G$6)) | D8: =BITXOR(C8,INT(C8/POWER(2,'Xorshift'!$G$7))) | E8: =BITXOR(D8,MOD(D8,POWER(2,32-'Xorshift'!$G$8))*POWER(2,'Xorshift'!$G$8))
A9: 4 | B9: =E8 | C9: =BITXOR(B9,MOD(B9,POWER(2,32-'Xorshift'!$G$6))*POWER(2,'Xorshift'!$G$6)) | D9: =BITXOR(C9,INT(C9/POWER(2,'Xorshift'!$G$7))) | E9: =BITXOR(D9,MOD(D9,POWER(2,32-'Xorshift'!$G$8))*POWER(2,'Xorshift'!$G$8))
A10: 5 | B10: =E9 | C10: =BITXOR(B10,MOD(B10,POWER(2,32-'Xorshift'!$G$6))*POWER(2,'Xorshift'!$G$6)) | D10: =BITXOR(C10,INT(C10/POWER(2,'Xorshift'!$G$7))) | E10: =BITXOR(D10,MOD(D10,POWER(2,32-'Xorshift'!$G$8))*POWER(2,'Xorshift'!$G$8))
A11: 6 | B11: =E10 | C11: =BITXOR(B11,MOD(B11,POWER(2,32-'Xorshift'!$G$6))*POWER(2,'Xorshift'!$G$6)) | D11: =BITXOR(C11,INT(C11/POWER(2,'Xorshift'!$G$7))) | E11: =BITXOR(D11,MOD(D11,POWER(2,32-'Xorshift'!$G$8))*POWER(2,'Xorshift'!$G$8))
A12: 7 | B12: =E11 | C12: =BITXOR(B12,MOD(B12,POWER(2,32-'Xorshift'!$G$6))*POWER(2,'Xorshift'!$G$6)) | D12: =BITXOR(C12,INT(C12/POWER(2,'Xorshift'!$G$7))) | E12: =BITXOR(D12,MOD(D12,POWER(2,32-'Xorshift'!$G$8))*POWER(2,'Xorshift'!$G$8))
A13: 8 | B13: =E12 | C13: =BITXOR(B13,MOD(B13,POWER(2,32-'Xorshift'!$G$6))*POWER(2,'Xorshift'!$G$6)) | D13: =BITXOR(C13,INT(C13/POWER(2,'Xorshift'!$G$7))) | E13: =BITXOR(D13,MOD(D13,POWER(2,32-'Xorshift'!$G$8))*POWER(2,'Xorshift'!$G$8))
A14: 9 | B14: =E13 | C14: =BITXOR(B14,MOD(B14,POWER(2,32-'Xorshift'!$G$6))*POWER(2,'Xorshift'!$G$6)) | D14: =BITXOR(C14,INT(C14/POWER(2,'Xorshift'!$G$7))) | E14: =BITXOR(D14,MOD(D14,POWER(2,32-'Xorshift'!$G$8))*POWER(2,'Xorshift'!$G$8))
A15: 10 | B15: =E14 | C15: =BITXOR(B15,MOD(B15,POWER(2,32-'Xorshift'!$G$6))*POWER(2,'Xorshift'!$G$6)) | D15: =BITXOR(C15,INT(C15/POWER(2,'Xorshift'!$G$7))) | E15: =BITXOR(D15,MOD(D15,POWER(2,32-'Xorshift'!$G$8))*POWER(2,'Xorshift'!$G$8))
A16: 11 | B16: =E15 | C16: =BITXOR(B16,MOD(B16,POWER(2,32-'Xorshift'!$G$6))*POWER(2,'Xorshift'!$G$6)) | D16: =BITXOR(C16,INT(C16/POWER(2,'Xorshift'!$G$7))) | E16: =BITXOR(D16,MOD(D16,POWER(2,32-'Xorshift'!$G$8))*POWER(2,'Xorshift'!$G$8))
A17: 12 | B17: =E16 | C17: =BITXOR(B17,MOD(B17,POWER(2,32-'Xorshift'!$G$6))*POWER(2,'Xorshift'!$G$6)) | D17: =BITXOR(C17,INT(C17/POWER(2,'Xorshift'!$G$7))) | E17: =BITXOR(D17,MOD(D17,POWER(2,32-'Xorshift'!$G$8))*POWER(2,'Xorshift'!$G$8))
A18: 13 | B18: =E17 | C18: =BITXOR(B18,MOD(B18,POWER(2,32-'Xorshift'!$G$6))*POWER(2,'Xorshift'!$G$6)) | D18: =BITXOR(C18,INT(C18/POWER(2,'Xorshift'!$G$7))) | E18: =BITXOR(D18,MOD(D18,POWER(2,32-'Xorshift'!$G$8))*POWER(2,'Xorshift'!$G$8))
... A25: 20 | B25: =E24 | C25: =BITXOR(B25,MOD(B25,POWER(2,32-'Xorshift'!$G$6))*POWER(2,'Xorshift'!$G$6)) | D25: =BITXOR(C25,INT(C25/POWER(2,'Xorshift'!$G$7))) | E25: =BITXOR(D25,MOD(D25,POWER(2,32-'Xorshift'!$G$8))*POWER(2,'Xorshift'!$G$8))
A28: 📐 Prueba de Promedios — Z_0
A29: Cantidad | B29: Valor
A30: Media (R̄) = AVERAGE(R_i) | B30: =AVERAGE('Xorshift'!$C$5:$C$24)
A31: N = COUNT(R_i) | B31: =COUNT('Xorshift'!$C$5:$C$24)
A32: Z_0 = (R̄-0.5)·√N / √(1/12) [sin valor absoluto] | B32: =(B30-0.5)*SQRT(B31)/SQRT(1/12)
A34: 📊 Prueba de Frecuencias / Entropía — Tabla de 10 clases
A35: Clase (k) | B35: Límite inf. | C35: Límite sup. | D35: Oi (observado) | E35: Ei (esperado) | F35: (Oi-Ei)²/Ei | G35: pi = Oi/N | H35: Aporte entropía -piㆍlog2(pi)
A36: 0 | B36: =A36/10 | C36: =(A36+1)/10 | D36: =COUNTIFS('Xorshift'!$C$5:$C$24,">="&B36,'Xorshift'!$C$5:$C$24,"<"&C36) | E36: =COUNT('Xorshift'!$C$5:$C$24)/10 | F36: =(D36-E36)^2/E36 | G36: =D36/COUNT('Xorshift'!$C$5:$C$24) | H36: =IF(D36>0,-G36*LOG(G36,2),0)
A37: 1 | B37: =A37/10 | C37: =(A37+1)/10 | D37: =COUNTIFS('Xorshift'!$C$5:$C$24,">="&B37,'Xorshift'!$C$5:$C$24,"<"&C37) | E37: =COUNT('Xorshift'!$C$5:$C$24)/10 | F37: =(D37-E37)^2/E37 | G37: =D37/COUNT('Xorshift'!$C$5:$C$24) | H37: =IF(D37>0,-G37*LOG(G37,2),0)
A38: 2 | B38: =A38/10 | C38: =(A38+1)/10 | D38: =COUNTIFS('Xorshift'!$C$5:$C$24,">="&B38,'Xorshift'!$C$5:$C$24,"<"&C38) | E38: =COUNT('Xorshift'!$C$5:$C$24)/10 | F38: =(D38-E38)^2/E38 | G38: =D38/COUNT('Xorshift'!$C$5:$C$24) | H38: =IF(D38>0,-G38*LOG(G38,2),0)
A39: 3 | B39: =A39/10 | C39: =(A39+1)/10 | D39: =COUNTIFS('Xorshift'!$C$5:$C$24,">="&B39,'Xorshift'!$C$5:$C$24,"<"&C39) | E39: =COUNT('Xorshift'!$C$5:$C$24)/10 | F39: =(D39-E39)^2/E39 | G39: =D39/COUNT('Xorshift'!$C$5:$C$24) | H39: =IF(D39>0,-G39*LOG(G39,2),0)
A40: 4 | B40: =A40/10 | C40: =(A40+1)/10 | D40: =COUNTIFS('Xorshift'!$C$5:$C$24,">="&B40,'Xorshift'!$C$5:$C$24,"<"&C40) | E40: =COUNT('Xorshift'!$C$5:$C$24)/10 | F40: =(D40-E40)^2/E40 | G40: =D40/COUNT('Xorshift'!$C$5:$C$24) | H40: =IF(D40>0,-G40*LOG(G40,2),0)
A41: 5 | B41: =A41/10 | C41: =(A41+1)/10 | D41: =COUNTIFS('Xorshift'!$C$5:$C$24,">="&B41,'Xorshift'!$C$5:$C$24,"<"&C41) | E41: =COUNT('Xorshift'!$C$5:$C$24)/10 | F41: =(D41-E41)^2/E41 | G41: =D41/COUNT('Xorshift'!$C$5:$C$24) | H41: =IF(D41>0,-G41*LOG(G41,2),0)
A42: 6 | B42: =A42/10 | C42: =(A42+1)/10 | D42: =COUNTIFS('Xorshift'!$C$5:$C$24,">="&B42,'Xorshift'!$C$5:$C$24,"<"&C42) | E42: =COUNT('Xorshift'!$C$5:$C$24)/10 | F42: =(D42-E42)^2/E42 | G42: =D42/COUNT('Xorshift'!$C$5:$C$24) | H42: =IF(D42>0,-G42*LOG(G42,2),0)
A43: 7 | B43: =A43/10 | C43: =(A43+1)/10 | D43: =COUNTIFS('Xorshift'!$C$5:$C$24,">="&B43,'Xorshift'!$C$5:$C$24,"<"&C43) | E43: =COUNT('Xorshift'!$C$5:$C$24)/10 | F43: =(D43-E43)^2/E43 | G43: =D43/COUNT('Xorshift'!$C$5:$C$24) | H43: =IF(D43>0,-G43*LOG(G43,2),0)
A44: 8 | B44: =A44/10 | C44: =(A44+1)/10 | D44: =COUNTIFS('Xorshift'!$C$5:$C$24,">="&B44,'Xorshift'!$C$5:$C$24,"<"&C44) | E44: =COUNT('Xorshift'!$C$5:$C$24)/10 | F44: =(D44-E44)^2/E44 | G44: =D44/COUNT('Xorshift'!$C$5:$C$24) | H44: =IF(D44>0,-G44*LOG(G44,2),0)
A45: 9 | B45: =A45/10 | C45: 1 | D45: =COUNTIFS('Xorshift'!$C$5:$C$24,">="&B45) | E45: =COUNT('Xorshift'!$C$5:$C$24)/10 | F45: =(D45-E45)^2/E45 | G45: =D45/COUNT('Xorshift'!$C$5:$C$24) | H45: =IF(D45>0,-G45*LOG(G45,2),0)
A47: 📈 Kolmogorov-Smirnov — R_i ordenados ascendentemente
A48: k | B48: R(k) [k-ésimo menor] | C48: k/N | D48: |k/N - R(k)|
A49: 1 | B49: =SMALL('Xorshift'!$C$5:$C$24,A49) | C49: =A49/COUNT('Xorshift'!$C$5:$C$24) | D49: =ABS(C49-B49)
A50: 2 | B50: =SMALL('Xorshift'!$C$5:$C$24,A50) | C50: =A50/COUNT('Xorshift'!$C$5:$C$24) | D50: =ABS(C50-B50)
A51: 3 | B51: =SMALL('Xorshift'!$C$5:$C$24,A51) | C51: =A51/COUNT('Xorshift'!$C$5:$C$24) | D51: =ABS(C51-B51)
...
